Workbook
Name PCT_LOLI: INGRESOS!$B$11
Name PCT_TITO: INGRESOS!$C$11

Sheet INGRESOS
A1: FINANZAS · LOLI & TITO
A3: INGRESOS NETOS MENSUALES
A4: Persona | B4: Ingreso | C4: % real | D4: Proporcional real (referencia)
A5: Loli | B5: 2800000 | C5: =B5/$B$7
A6: Tito | B6: 4000000 | C6: =B6/$B$7
A7: Total | B7: =B5+B6 | C7: =B7/$B$7
A9: SPLIT EN USO (editable)
A10: Concepto | B10: % Loli | C10: % Tito | D10: Notas
A11: Split actual | B11: 0.4 | C11: =1-B11 | D11: Cambiá solo la celda amarilla (% Loli). Tito se ajusta solo.
A13: MONTOS FIJOS DE REFERENCIA
A14: Concepto | B14: Núñez | C14: Pilar
A15: Expensas | B15: 415277 | C15: 336690
A16: Luz (EDENOR) | B16: 52392
A17: Gas
A18: Agua
A19: Wifi (Telecentro) | B19: 38940
A20: Limpieza | B20: 198000 | C20: 63000
A21: Paseadora Antonio | B21: 98000
A22: Netflix / Streaming | B22: 22648
A23: Pilates
A24: ABL / ARBA
A25: Seguro hogar
A27: Todas las celdas amarillas son editables. Si pisás una fórmula perdés el cálculo automático de esa celda, pero el archivo no se rompe.

Sheet JUNIO
A1: JUNIO 2026
A3: CONTROL DEL MES
A4: Aporte Loli | B4: Aporte Tito | C4: Sobró del mes anterior | D4: =Total disponible | E4: Total gastado | F4: FALTÓ | G4: SOBRÓ (pasa →)
A5: 1000000 | B5: 1500000 | C5: 0 | D5: =A5+B5+C5 | E5: =B25+D59 | F5: =MAX(0,E5-D5) | G5: =MAX(0,D5-E5)
A8: GASTOS FIJOS · monto y medio de pago
A9: Concepto | B9: Monto | C9: Medio de pago
A10: Expensas Núñez | C10: AMEX Loli
A11: Expensas Pilar | B11: 398000 | C11: AMEX Loli
A12: Luz Núñez | B12: 52392 | C12: AMEX Loli
A13: Luz Pilar | C13: AMEX Loli
A14: Wifi Núñez | B14: 38940 | C14: AMEX Loli
A15: Wifi Pilar | C15: AMEX Loli
A16: Paseadora Antonio | C16: Transferencia
A17: Limpieza Núñez | C17: Transferencia
A18: Limpieza Pilar | C18: Transferencia
A19: Netflix | B19: 22648 | C19: AMEX Loli
A20: Pilates | C20: Transferencia
A25: Subtotal fijos | B25: =SUM(B10:B24)
A27: GASTOS AMEX / TARJETA · por categoría (se acomoda solo)
A28: Detalle / Comercio | B28: Categoría (auto) | C28: Casa | D28: Monto | E28: Medio de pago
A29: Hamburguesería Colegiales | B29: =IF($A29="","",IFERROR(LOOKUP(2,1/((ISNUMBER(SEARCH(CONFIG!$A$3:$A$94,$A29)))*(CONFIG!$A$3:$A$94<>"")),CONFIG!$B$3:$B$94),"Otros")) | C29: Ambos | D29: 47000 | E29: AMEX Loli
B30: =IF($A30="","",IFERROR(LOOKUP(2,1/((ISNUMBER(SEARCH(CONFIG!$A$3:$A$94,$A30)))*(CONFIG!$A$3:$A$94<>"")),CONFIG!$B$3:$B$94),"Otros"))
B31: =IF($A31="","",IFERROR(LOOKUP(2,1/((ISNUMBER(SEARCH(CONFIG!$A$3:$A$94,$A31)))*(CONFIG!$A$3:$A$94<>"")),CONFIG!$B$3:$B$94),"Otros"))
B32: =IF($A32="","",IFERROR(LOOKUP(2,1/((ISNUMBER(SEARCH(CONFIG!$A$3:$A$94,$A32)))*(CONFIG!$A$3:$A$94<>"")),CONFIG!$B$3:$B$94),"Otros"))
B33: =IF($A33="","",IFERROR(LOOKUP(2,1/((ISNUMBER(SEARCH(CONFIG!$A$3:$A$94,$A33)))*(CONFIG!$A$3:$A$94<>"")),CONFIG!$B$3:$B$94),"Otros"))
B34: =IF($A34="","",IFERROR(LOOKUP(2,1/((ISNUMBER(SEARCH(CONFIG!$A$3:$A$94,$A34)))*(CONFIG!$A$3:$A$94<>"")),CONFIG!$B$3:$B$94),"Otros"))
B35: =IF($A35="","",IFERROR(LOOKUP(2,1/((ISNUMBER(SEARCH(CONFIG!$A$3:$A$94,$A35)))*(CONFIG!$A$3:$A$94<>"")),CONFIG!$B$3:$B$94),"Otros"))
B36: =IF($A36="","",IFERROR(LOOKUP(2,1/((ISNUMBER(SEARCH(CONFIG!$A$3:$A$94,$A36)))*(CONFIG!$A$3:$A$94<>"")),CONFIG!$B$3:$B$94),"Otros"))
B37: =IF($A37="","",IFERROR(LOOKUP(2,1/((ISNUMBER(SEARCH(CONFIG!$A$3:$A$94,$A37)))*(CONFIG!$A$3:$A$94<>"")),CONFIG!$B$3:$B$94),"Otros"))
B38: =IF($A38="","",IFERROR(LOOKUP(2,1/((ISNUMBER(SEARCH(CONFIG!$A$3:$A$94,$A38)))*(CONFIG!$A$3:$A$94<>"")),CONFIG!$B$3:$B$94),"Otros"))
B39: =IF($A39="","",IFERROR(LOOKUP(2,1/((ISNUMBER(SEARCH(CONFIG!$A$3:$A$94,$A39)))*(CONFIG!$A$3:$A$94<>"")),CONFIG!$B$3:$B$94),"Otros"))
B40: =IF($A40="","",IFERROR(LOOKUP(2,1/((ISNUMBER(SEARCH(CONFIG!$A$3:$A$94,$A40)))*(CONFIG!$A$3:$A$94<>"")),CONFIG!$B$3:$B$94),"Otros"))
B41: =IF($A41="","",IFERROR(LOOKUP(2,1/((ISNUMBER(SEARCH(CONFIG!$A$3:$A$94,$A41)))*(CONFIG!$A$3:$A$94<>"")),CONFIG!$B$3:$B$94),"Otros"))
... B58: =IF($A58="","",IFERROR(LOOKUP(2,1/((ISNUMBER(SEARCH(CONFIG!$A$3:$A$94,$A58)))*(CONFIG!$A$3:$A$94<>"")),CONFIG!$B$3:$B$94),"Otros"))
A59: Subtotal AMEX / tarjeta | D59: =SUM(D29:D58)
A60: ➤ Pegá acá el resumen de la AMEX (Detalle + Monto). La categoría se completa sola según el mapa de la hoja CONFIG. No hace falta crear otro archivo.
A62: RESUMEN · EN QUÉ SE GASTÓ MÁS
A63: Por sección | B63: Monto | C63: % del total
A64: Gastos fijos | B64: =$B$25 | C64: =IF(($B$25+$D$59)=0,0,($B$25)/($B$25+$D$59))
A65: Gastos AMEX / tarjeta | B65: =$D$59 | C65: =IF(($B$25+$D$59)=0,0,($D$59)/($B$25+$D$59))
...

Sheet JULIO
A1: JULIO 2026
A3: CONTROL DEL MES
A4: Aporte Loli | B4: Aporte Tito | C4: Sobró del mes anterior | D4: =Total disponible | E4: Total gastado | F4: FALTÓ | G4: SOBRÓ (pasa →)
A5: 1000000 | B5: 2000000 | C5: ='JUNIO'!$G$5 | D5: =A5+B5+C5 | E5: =B25+D65 | F5: =MAX(0,E5-D5) | G5: =MAX(0,D5-E5)
A8: GASTOS FIJOS · monto y medio de pago
A9: Concepto | B9: Monto | C9: Medio de pago
A10: Expensas Núñez | B10: 415000 | C10: AMEX Loli
A11: Expensas Pilar | B11: 398000 | C11: AMEX Loli
A12: Luz Núñez | B12: 21318 | C12: AMEX Loli
A13: Luz Pilar | B13: 24579 | C13: AMEX Loli
A14: Wifi Núñez | B14: 44898 | C14: AMEX Loli
A15: Wifi Pilar | B15: 45238 | C15: AMEX Loli
A16: Paseadora Antonio | B16: 98000 | C16: Transferencia
A17: Limpieza Núñez | B17: 198000 | C17: Transferencia
A18: Limpieza Pilar | B18: 63000 | C18: Transferencia
A19: Netflix | B19: 22648 | C19: AMEX Loli
A20: Pilates | C20: Transferencia
A25: Subtotal fijos | B25: =SUM(B10:B24)
A27: GASTOS AMEX / TARJETA · por categoría (se acomoda solo)
A28: Detalle / Comercio | B28: Categoría (auto) | C28: Casa | D28: Monto | E28: Medio de pago
A29: Merpago Delfin | B29: =IF($A29="","",IFERROR(LOOKUP(2,1/((ISNUMBER(SEARCH(CONFIG!$A$3:$A$94,$A29)))*(CONFIG!$A$3:$A$94<>"")),CONFIG!$B$3:$B$94),"Otros")) | C29: Núñez | D29: 23500 | E29: AMEX Loli
A30: Groovypets | B30: =IF($A30="","",IFERROR(LOOKUP(2,1/((ISNUMBER(SEARCH(CONFIG!$A$3:$A$94,$A30)))*(CONFIG!$A$3:$A$94<>"")),CONFIG!$B$3:$B$94),"Otros")) | C30: Ambos | D30: 50900 | E30: AMEX Loli
A31: Merpago-h2soap | B31: =IF($A31="","",IFERROR(LOOKUP(2,1/((ISNUMBER(SEARCH(CONFIG!$A$3:$A$94,$A31)))*(CONFIG!$A$3:$A$94<>"")),CONFIG!$B$3:$B$94),"Otros")) | C31: Ambos | D31: 14944 | E31: AMEX Loli
A32: Groovypets | B32: =IF($A32="","",IFERROR(LOOKUP(2,1/((ISNUMBER(SEARCH(CONFIG!$A$3:$A$94,$A32)))*(CONFIG!$A$3:$A$94<>"")),CONFIG!$B$3:$B$94),"Otros")) | C32: Ambos | D32: 44500 | E32: AMEX Loli
A33: Rappi | B33: =IF($A33="","",IFERROR(LOOKUP(2,1/((ISNUMBER(SEARCH(CONFIG!$A$3:$A$94,$A33)))*(CONFIG!$A$3:$A$94<>"")),CONFIG!$B$3:$B$94),"Otros")) | C33: Núñez | D33: 50897 | E33: AMEX Loli
A34: Super Manzanares | B34: =IF($A34="","",IFERROR(LOOKUP(2,1/((ISNUMBER(SEARCH(CONFIG!$A$3:$A$94,$A34)))*(CONFIG!$A$3:$A$94<>"")),CONFIG!$B$3:$B$94),"Otros")) | C34: Núñez | D34: 25000 | E34: AMEX Loli
A35: Pedidos Ya market | B35: =IF($A35="","",IFERROR(LOOKUP(2,1/((ISNUMBER(SEARCH(CONFIG!$A$3:$A$94,$A35)))*(CONFIG!$A$3:$A$94<>"")),CONFIG!$B$3:$B$94),"Otros")) | C35: Núñez | D35: 34800 | E35: AMEX Loli
A36: Rappi Super | B36: =IF($A36="","",IFERROR(LOOKUP(2,1/((ISNUMBER(SEARCH(CONFIG!$A$3:$A$94,$A36)))*(CONFIG!$A$3:$A$94<>"")),CONFIG!$B$3:$B$94),"Otros")) | C36: Núñez | D36: 156500 | E36: AMEX Loli
A37: La Noire Café + Razo-Razo | B37: =IF($A37="","",IFERROR(LOOKUP(2,1/((ISNUMBER(SEARCH(CONFIG!$A$3:$A$94,$A37)))*(CONFIG!$A$3:$A$94<>"")),CONFIG!$B$3:$B$94),"Otros")) | C37: Ambos | D37: 48900 | E37: AMEX Loli
A38: Merpago Delfin + Super Paroissien | B38: =IF($A38="","",IFERROR(LOOKUP(2,1/((ISNUMBER(SEARCH(CONFIG!$A$3:$A$94,$A38)))*(CONFIG!$A$3:$A$94<>"")),CONFIG!$B$3:$B$94),"Otros")) | C38: Núñez | D38: 92000 | E38: AMEX Loli
A39: Solileb | B39: =IF($A39="","",IFERROR(LOOKUP(2,1/((ISNUMBER(SEARCH(CONFIG!$A$3:$A$94,$A39)))*(CONFIG!$A$3:$A$94<>"")),CONFIG!$B$3:$B$94),"Otros")) | C39: Ambos | D39: 74000 | E39: AMEX Loli
A40: Rappi | B40: =IF($A40="","",IFERROR(LOOKUP(2,1/((ISNUMBER(SEARCH(CONFIG!$A$3:$A$94,$A40)))*(CONFIG!$A$3:$A$94<>"")),CONFIG!$B$3:$B$94),"Otros")) | C40: Ambos | D40: 22162 | E40: AMEX Loli
... A52: Evelia | B52: =IF($A52="","",IFERROR(LOOKUP(2,1/((ISNUMBER(SEARCH(CONFIG!$A$3:$A$94,$A52)))*(CONFIG!$A$3:$A$94<>"")),CONFIG!$B$3:$B$94),"Otros")) | C52: Ambos | D52: 160400 | E52: AMEX Loli
B53: =IF($A53="","",IFERROR(LOOKUP(2,1/((ISNUMBER(SEARCH(CONFIG!$A$3:$A$94,$A53)))*(CONFIG!$A$3:$A$94<>"")),CONFIG!$B$3:$B$94),"Otros"))
B54: =IF($A54="","",IFERROR(LOOKUP(2,1/((ISNUMBER(SEARCH(CONFIG!$A$3:$A$94,$A54)))*(CONFIG!$A$3:$A$94<>"")),CONFIG!$B$3:$B$94),"Otros"))
B55: =IF($A55="","",IFERROR(LOOKUP(2,1/((ISNUMBER(SEARCH(CONFIG!$A$3:$A$94,$A55)))*(CONFIG!$A$3:$A$94<>"")),CONFIG!$B$3:$B$94),"Otros"))
B56: =IF($A56="","",IFERROR(LOOKUP(2,1/((ISNUMBER(SEARCH(CONFIG!$A$3:$A$94,$A56)))*(CONFIG!$A$3:$A$94<>"")),CONFIG!$B$3:$B$94),"Otros"))
B57: =IF($A57="","",IFERROR(LOOKUP(2,1/((ISNUMBER(SEARCH(CONFIG!$A$3:$A$94,$A57)))*(CONFIG!$A$3:$A$94<>"")),CONFIG!$B$3:$B$94),"Otros"))
B58: =IF($A58="","",IFERROR(LOOKUP(2,1/((ISNUMBER(SEARCH(CONFIG!$A$3:$A$94,$A58)))*(CONFIG!$A$3:$A$94<>"")),CONFIG!$B$3:$B$94),"Otros"))
B59: =IF($A59="","",IFERROR(LOOKUP(2,1/((ISNUMBER(SEARCH(CONFIG!$A$3:$A$94,$A59)))*(CONFIG!$A$3:$A$94<>"")),CONFIG!$B$3:$B$94),"Otros"))
...

Sheet AGOSTO
A1: AGOSTO 2026
A3: CONTROL DEL MES
A4: Aporte Loli | B4: Aporte Tito | C4: Sobró del mes anterior | D4: =Total disponible | E4: Total gastado | F4: FALTÓ | G4: SOBRÓ (pasa →)
A5: 0 | B5: 0 | C5: ='JULIO'!$G$5 | D5: =A5+B5+C5 | E5: =B25+D59 | F5: =MAX(0,E5-D5) | G5: =MAX(0,D5-E5)
A8: GASTOS FIJOS · monto y medio de pago
A9: Concepto | B9: Monto | C9: Medio de pago
A10: Expensas Núñez
A11: Expensas Pilar
A12: Luz Núñez
A13: Luz Pilar
A14: Wifi Núñez
A15: Wifi Pilar
A16: Paseadora Antonio
A17: Limpieza Núñez
A18: Limpieza Pilar
A19: Netflix
A20: Pilates
A25: Subtotal fijos | B25: =SUM(B10:B24)
A27: GASTOS AMEX / TARJETA · por categoría (se acomoda solo)
A28: Detalle / Comercio | B28: Categoría (auto) | C28: Casa | D28: Monto | E28: Medio de pago
B29: =IF($A29="","",IFERROR(LOOKUP(2,1/((ISNUMBER(SEARCH(CONFIG!$A$3:$A$94,$A29)))*(CONFIG!$A$3:$A$94<>"")),CONFIG!$B$3:$B$94),"Otros"))
B30: =IF($A30="","",IFERROR(LOOKUP(2,1/((ISNUMBER(SEARCH(CONFIG!$A$3:$A$94,$A30)))*(CONFIG!$A$3:$A$94<>"")),CONFIG!$B$3:$B$94),"Otros"))
B31: =IF($A31="","",IFERROR(LOOKUP(2,1/((ISNUMBER(SEARCH(CONFIG!$A$3:$A$94,$A31)))*(CONFIG!$A$3:$A$94<>"")),CONFIG!$B$3:$B$94),"Otros"))
B32: =IF($A32="","",IFERROR(LOOKUP(2,1/((ISNUMBER(SEARCH(CONFIG!$A$3:$A$94,$A32)))*(CONFIG!$A$3:$A$94<>"")),CONFIG!$B$3:$B$94),"Otros"))
B33: =IF($A33="","",IFERROR(LOOKUP(2,1/((ISNUMBER(SEARCH(CONFIG!$A$3:$A$94,$A33)))*(CONFIG!$A$3:$A$94<>"")),CONFIG!$B$3:$B$94),"Otros"))
B34: =IF($A34="","",IFERROR(LOOKUP(2,1/((ISNUMBER(SEARCH(CONFIG!$A$3:$A$94,$A34)))*(CONFIG!$A$3:$A$94<>"")),CONFIG!$B$3:$B$94),"Otros"))
B35: =IF($A35="","",IFERROR(LOOKUP(2,1/((ISNUMBER(SEARCH(CONFIG!$A$3:$A$94,$A35)))*(CONFIG!$A$3:$A$94<>"")),CONFIG!$B$3:$B$94),"Otros"))
B36: =IF($A36="","",IFERROR(LOOKUP(2,1/((ISNUMBER(SEARCH(CONFIG!$A$3:$A$94,$A36)))*(CONFIG!$A$3:$A$94<>"")),CONFIG!$B$3:$B$94),"Otros"))
B37: =IF($A37="","",IFERROR(LOOKUP(2,1/((ISNUMBER(SEARCH(CONFIG!$A$3:$A$94,$A37)))*(CONFIG!$A$3:$A$94<>"")),CONFIG!$B$3:$B$94),"Otros"))
B38: =IF($A38="","",IFERROR(LOOKUP(2,1/((ISNUMBER(SEARCH(CONFIG!$A$3:$A$94,$A38)))*(CONFIG!$A$3:$A$94<>"")),CONFIG!$B$3:$B$94),"Otros"))
B39: =IF($A39="","",IFERROR(LOOKUP(2,1/((ISNUMBER(SEARCH(CONFIG!$A$3:$A$94,$A39)))*(CONFIG!$A$3:$A$94<>"")),CONFIG!$B$3:$B$94),"Otros"))
B40: =IF($A40="","",IFERROR(LOOKUP(2,1/((ISNUMBER(SEARCH(CONFIG!$A$3:$A$94,$A40)))*(CONFIG!$A$3:$A$94<>"")),CONFIG!$B$3:$B$94),"Otros"))
... B58: =IF($A58="","",IFERROR(LOOKUP(2,1/((ISNUMBER(SEARCH(CONFIG!$A$3:$A$94,$A58)))*(CONFIG!$A$3:$A$94<>"")),CONFIG!$B$3:$B$94),"Otros"))
A59: Subtotal AMEX / tarjeta | D59: =SUM(D29:D58)
A60: ➤ Pegá acá el resumen de la AMEX (Detalle + Monto). La categoría se completa sola según el mapa de la hoja CONFIG. No hace falta crear otro archivo.
A62: RESUMEN · EN QUÉ SE GASTÓ MÁS
A63: Por sección | B63: Monto | C63: % del total
A64: Gastos fijos | B64: =$B$25 | C64: =IF(($B$25+$D$59)=0,0,($B$25)/($B$25+$D$59))
A65: Gastos AMEX / tarjeta | B65: =$D$59 | C65: =IF(($B$25+$D$59)=0,0,($D$59)/($B$25+$D$59))
A66: TOTAL | B66: =$B$25+$D$59 | C66: =IF(($B$25+$D$59)=0,0,1)
...

Sheet SEPTIEMBRE
A1: SEPTIEMBRE 2026
A3: CONTROL DEL MES
A4: Aporte Loli | B4: Aporte Tito | C4: Sobró del mes anterior | D4: =Total disponible | E4: Total gastado | F4: FALTÓ | G4: SOBRÓ (pasa →)
A5: 0 | B5: 0 | C5: ='AGOSTO'!$G$5 | D5: =A5+B5+C5 | E5: =B25+D59 | F5: =MAX(0,E5-D5) | G5: =MAX(0,D5-E5)
A8: GASTOS FIJOS · monto y medio de pago
A9: Concepto | B9: Monto | C9: Medio de pago
A10: Expensas Núñez
A11: Expensas Pilar
A12: Luz Núñez
A13: Luz Pilar
A14: Wifi Núñez
A15: Wifi Pilar
A16: Paseadora Antonio
A17: Limpieza Núñez
A18: Limpieza Pilar
A19: Netflix
A20: Pilates
A25: Subtotal fijos | B25: =SUM(B10:B24)
A27: GASTOS AMEX / TARJETA · por categoría (se acomoda solo)
A28: Detalle / Comercio | B28: Categoría (auto) | C28: Casa | D28: Monto | E28: Medio de pago
B29: =IF($A29="","",IFERROR(LOOKUP(2,1/((ISNUMBER(SEARCH(CONFIG!$A$3:$A$94,$A29)))*(CONFIG!$A$3:$A$94<>"")),CONFIG!$B$3:$B$94),"Otros"))
B30: =IF($A30="","",IFERROR(LOOKUP(2,1/((ISNUMBER(SEARCH(CONFIG!$A$3:$A$94,$A30)))*(CONFIG!$A$3:$A$94<>"")),CONFIG!$B$3:$B$94),"Otros"))
B31: =IF($A31="","",IFERROR(LOOKUP(2,1/((ISNUMBER(SEARCH(CONFIG!$A$3:$A$94,$A31)))*(CONFIG!$A$3:$A$94<>"")),CONFIG!$B$3:$B$94),"Otros"))
B32: =IF($A32="","",IFERROR(LOOKUP(2,1/((ISNUMBER(SEARCH(CONFIG!$A$3:$A$94,$A32)))*(CONFIG!$A$3:$A$94<>"")),CONFIG!$B$3:$B$94),"Otros"))
B33: =IF($A33="","",IFERROR(LOOKUP(2,1/((ISNUMBER(SEARCH(CONFIG!$A$3:$A$94,$A33)))*(CONFIG!$A$3:$A$94<>"")),CONFIG!$B$3:$B$94),"Otros"))
B34: =IF($A34="","",IFERROR(LOOKUP(2,1/((ISNUMBER(SEARCH(CONFIG!$A$3:$A$94,$A34)))*(CONFIG!$A$3:$A$94<>"")),CONFIG!$B$3:$B$94),"Otros"))
B35: =IF($A35="","",IFERROR(LOOKUP(2,1/((ISNUMBER(SEARCH(CONFIG!$A$3:$A$94,$A35)))*(CONFIG!$A$3:$A$94<>"")),CONFIG!$B$3:$B$94),"Otros"))
B36: =IF($A36="","",IFERROR(LOOKUP(2,1/((ISNUMBER(SEARCH(CONFIG!$A$3:$A$94,$A36)))*(CONFIG!$A$3:$A$94<>"")),CONFIG!$B$3:$B$94),"Otros"))
B37: =IF($A37="","",IFERROR(LOOKUP(2,1/((ISNUMBER(SEARCH(CONFIG!$A$3:$A$94,$A37)))*(CONFIG!$A$3:$A$94<>"")),CONFIG!$B$3:$B$94),"Otros"))
B38: =IF($A38="","",IFERROR(LOOKUP(2,1/((ISNUMBER(SEARCH(CONFIG!$A$3:$A$94,$A38)))*(CONFIG!$A$3:$A$94<>"")),CONFIG!$B$3:$B$94),"Otros"))
B39: =IF($A39="","",IFERROR(LOOKUP(2,1/((ISNUMBER(SEARCH(CONFIG!$A$3:$A$94,$A39)))*(CONFIG!$A$3:$A$94<>"")),CONFIG!$B$3:$B$94),"Otros"))
B40: =IF($A40="","",IFERROR(LOOKUP(2,1/((ISNUMBER(SEARCH(CONFIG!$A$3:$A$94,$A40)))*(CONFIG!$A$3:$A$94<>"")),CONFIG!$B$3:$B$94),"Otros"))
... B58: =IF($A58="","",IFERROR(LOOKUP(2,1/((ISNUMBER(SEARCH(CONFIG!$A$3:$A$94,$A58)))*(CONFIG!$A$3:$A$94<>"")),CONFIG!$B$3:$B$94),"Otros"))
A59: Subtotal AMEX / tarjeta | D59: =SUM(D29:D58)
A60: ➤ Pegá acá el resumen de la AMEX (Detalle + Monto). La categoría se completa sola según el mapa de la hoja CONFIG. No hace falta crear otro archivo.
A62: RESUMEN · EN QUÉ SE GASTÓ MÁS
A63: Por sección | B63: Monto | C63: % del total
A64: Gastos fijos | B64: =$B$25 | C64: =IF(($B$25+$D$59)=0,0,($B$25)/($B$25+$D$59))
A65: Gastos AMEX / tarjeta | B65: =$D$59 | C65: =IF(($B$25+$D$59)=0,0,($D$59)/($B$25+$D$59))
A66: TOTAL | B66: =$B$25+$D$59 | C66: =IF(($B$25+$D$59)=0,0,1)
...

Sheet OCTUBRE
A1: OCTUBRE 2026
A3: CONTROL DEL MES
A4: Aporte Loli | B4: Aporte Tito | C4: Sobró del mes anterior | D4: =Total disponible | E4: Total gastado | F4: FALTÓ | G4: SOBRÓ (pasa →)
A5: 0 | B5: 0 | C5: ='SEPTIEMBRE'!$G$5 | D5: =A5+B5+C5 | E5: =B25+D59 | F5: =MAX(0,E5-D5) | G5: =MAX(0,D5-E5)
A8: GASTOS FIJOS · monto y medio de pago
A9: Concepto | B9: Monto | C9: Medio de pago
A10: Expensas Núñez
A11: Expensas Pilar
A12: Luz Núñez
A13: Luz Pilar
A14: Wifi Núñez
A15: Wifi Pilar
A16: Paseadora Antonio
A17: Limpieza Núñez
A18: Limpieza Pilar
A19: Netflix
A20: Pilates
A25: Subtotal fijos | B25: =SUM(B10:B24)
A27: GASTOS AMEX / TARJETA · por categoría (se acomoda solo)
A28: Detalle / Comercio | B28: Categoría (auto) | C28: Casa | D28: Monto | E28: Medio de pago
B29: =IF($A29="","",IFERROR(LOOKUP(2,1/((ISNUMBER(SEARCH(CONFIG!$A$3:$A$94,$A29)))*(CONFIG!$A$3:$A$94<>"")),CONFIG!$B$3:$B$94),"Otros"))
B30: =IF($A30="","",IFERROR(LOOKUP(2,1/((ISNUMBER(SEARCH(CONFIG!$A$3:$A$94,$A30)))*(CONFIG!$A$3:$A$94<>"")),CONFIG!$B$3:$B$94),"Otros"))
B31: =IF($A31="","",IFERROR(LOOKUP(2,1/((ISNUMBER(SEARCH(CONFIG!$A$3:$A$94,$A31)))*(CONFIG!$A$3:$A$94<>"")),CONFIG!$B$3:$B$94),"Otros"))
B32: =IF($A32="","",IFERROR(LOOKUP(2,1/((ISNUMBER(SEARCH(CONFIG!$A$3:$A$94,$A32)))*(CONFIG!$A$3:$A$94<>"")),CONFIG!$B$3:$B$94),"Otros"))
B33: =IF($A33="","",IFERROR(LOOKUP(2,1/((ISNUMBER(SEARCH(CONFIG!$A$3:$A$94,$A33)))*(CONFIG!$A$3:$A$94<>"")),CONFIG!$B$3:$B$94),"Otros"))
B34: =IF($A34="","",IFERROR(LOOKUP(2,1/((ISNUMBER(SEARCH(CONFIG!$A$3:$A$94,$A34)))*(CONFIG!$A$3:$A$94<>"")),CONFIG!$B$3:$B$94),"Otros"))
B35: =IF($A35="","",IFERROR(LOOKUP(2,1/((ISNUMBER(SEARCH(CONFIG!$A$3:$A$94,$A35)))*(CONFIG!$A$3:$A$94<>"")),CONFIG!$B$3:$B$94),"Otros"))
B36: =IF($A36="","",IFERROR(LOOKUP(2,1/((ISNUMBER(SEARCH(CONFIG!$A$3:$A$94,$A36)))*(CONFIG!$A$3:$A$94<>"")),CONFIG!$B$3:$B$94),"Otros"))
B37: =IF($A37="","",IFERROR(LOOKUP(2,1/((ISNUMBER(SEARCH(CONFIG!$A$3:$A$94,$A37)))*(CONFIG!$A$3:$A$94<>"")),CONFIG!$B$3:$B$94),"Otros"))
B38: =IF($A38="","",IFERROR(LOOKUP(2,1/((ISNUMBER(SEARCH(CONFIG!$A$3:$A$94,$A38)))*(CONFIG!$A$3:$A$94<>"")),CONFIG!$B$3:$B$94),"Otros"))
B39: =IF($A39="","",IFERROR(LOOKUP(2,1/((ISNUMBER(SEARCH(CONFIG!$A$3:$A$94,$A39)))*(CONFIG!$A$3:$A$94<>"")),CONFIG!$B$3:$B$94),"Otros"))
B40: =IF($A40="","",IFERROR(LOOKUP(2,1/((ISNUMBER(SEARCH(CONFIG!$A$3:$A$94,$A40)))*(CONFIG!$A$3:$A$94<>"")),CONFIG!$B$3:$B$94),"Otros"))
... B58: =IF($A58="","",IFERROR(LOOKUP(2,1/((ISNUMBER(SEARCH(CONFIG!$A$3:$A$94,$A58)))*(CONFIG!$A$3:$A$94<>"")),CONFIG!$B$3:$B$94),"Otros"))
A59: Subtotal AMEX / tarjeta | D59: =SUM(D29:D58)
A60: ➤ Pegá acá el resumen de la AMEX (Detalle + Monto). La categoría se completa sola según el mapa de la hoja CONFIG. No hace falta crear otro archivo.
A62: RESUMEN · EN QUÉ SE GASTÓ MÁS
A63: Por sección | B63: Monto | C63: % del total
A64: Gastos fijos | B64: =$B$25 | C64: =IF(($B$25+$D$59)=0,0,($B$25)/($B$25+$D$59))
A65: Gastos AMEX / tarjeta | B65: =$D$59 | C65: =IF(($B$25+$D$59)=0,0,($D$59)/($B$25+$D$59))
A66: TOTAL | B66: =$B$25+$D$59 | C66: =IF(($B$25+$D$59)=0,0,1)
...

Sheet NOVIEMBRE
A1: NOVIEMBRE 2026
A3: CONTROL DEL MES
A4: Aporte Loli | B4: Aporte Tito | C4: Sobró del mes anterior | D4: =Total disponible | E4: Total gastado | F4: FALTÓ | G4: SOBRÓ (pasa →)
A5: 0 | B5: 0 | C5: ='OCTUBRE'!$G$5 | D5: =A5+B5+C5 | E5: =B25+D59 | F5: =MAX(0,E5-D5) | G5: =MAX(0,D5-E5)
A8: GASTOS FIJOS · monto y medio de pago
A9: Concepto | B9: Monto | C9: Medio de pago
A10: Expensas Núñez
A11: Expensas Pilar
A12: Luz Núñez
A13: Luz Pilar
A14: Wifi Núñez
A15: Wifi Pilar
A16: Paseadora Antonio
A17: Limpieza Núñez
A18: Limpieza Pilar
A19: Netflix
A20: Pilates
A25: Subtotal fijos | B25: =SUM(B10:B24)
A27: GASTOS AMEX / TARJETA · por categoría (se acomoda solo)
A28: Detalle / Comercio | B28: Categoría (auto) | C28: Casa | D28: Monto | E28: Medio de pago
B29: =IF($A29="","",IFERROR(LOOKUP(2,1/((ISNUMBER(SEARCH(CONFIG!$A$3:$A$94,$A29)))*(CONFIG!$A$3:$A$94<>"")),CONFIG!$B$3:$B$94),"Otros"))
B30: =IF($A30="","",IFERROR(LOOKUP(2,1/((ISNUMBER(SEARCH(CONFIG!$A$3:$A$94,$A30)))*(CONFIG!$A$3:$A$94<>"")),CONFIG!$B$3:$B$94),"Otros"))
B31: =IF($A31="","",IFERROR(LOOKUP(2,1/((ISNUMBER(SEARCH(CONFIG!$A$3:$A$94,$A31)))*(CONFIG!$A$3:$A$94<>"")),CONFIG!$B$3:$B$94),"Otros"))
B32: =IF($A32="","",IFERROR(LOOKUP(2,1/((ISNUMBER(SEARCH(CONFIG!$A$3:$A$94,$A32)))*(CONFIG!$A$3:$A$94<>"")),CONFIG!$B$3:$B$94),"Otros"))
B33: =IF($A33="","",IFERROR(LOOKUP(2,1/((ISNUMBER(SEARCH(CONFIG!$A$3:$A$94,$A33)))*(CONFIG!$A$3:$A$94<>"")),CONFIG!$B$3:$B$94),"Otros"))
B34: =IF($A34="","",IFERROR(LOOKUP(2,1/((ISNUMBER(SEARCH(CONFIG!$A$3:$A$94,$A34)))*(CONFIG!$A$3:$A$94<>"")),CONFIG!$B$3:$B$94),"Otros"))
B35: =IF($A35="","",IFERROR(LOOKUP(2,1/((ISNUMBER(SEARCH(CONFIG!$A$3:$A$94,$A35)))*(CONFIG!$A$3:$A$94<>"")),CONFIG!$B$3:$B$94),"Otros"))
B36: =IF($A36="","",IFERROR(LOOKUP(2,1/((ISNUMBER(SEARCH(CONFIG!$A$3:$A$94,$A36)))*(CONFIG!$A$3:$A$94<>"")),CONFIG!$B$3:$B$94),"Otros"))
B37: =IF($A37="","",IFERROR(LOOKUP(2,1/((ISNUMBER(SEARCH(CONFIG!$A$3:$A$94,$A37)))*(CONFIG!$A$3:$A$94<>"")),CONFIG!$B$3:$B$94),"Otros"))
B38: =IF($A38="","",IFERROR(LOOKUP(2,1/((ISNUMBER(SEARCH(CONFIG!$A$3:$A$94,$A38)))*(CONFIG!$A$3:$A$94<>"")),CONFIG!$B$3:$B$94),"Otros"))
B39: =IF($A39="","",IFERROR(LOOKUP(2,1/((ISNUMBER(SEARCH(CONFIG!$A$3:$A$94,$A39)))*(CONFIG!$A$3:$A$94<>"")),CONFIG!$B$3:$B$94),"Otros"))
B40: =IF($A40="","",IFERROR(LOOKUP(2,1/((ISNUMBER(SEARCH(CONFIG!$A$3:$A$94,$A40)))*(CONFIG!$A$3:$A$94<>"")),CONFIG!$B$3:$B$94),"Otros"))
... B58: =IF($A58="","",IFERROR(LOOKUP(2,1/((ISNUMBER(SEARCH(CONFIG!$A$3:$A$94,$A58)))*(CONFIG!$A$3:$A$94<>"")),CONFIG!$B$3:$B$94),"Otros"))
A59: Subtotal AMEX / tarjeta | D59: =SUM(D29:D58)
A60: ➤ Pegá acá el resumen de la AMEX (Detalle + Monto). La categoría se completa sola según el mapa de la hoja CONFIG. No hace falta crear otro archivo.
A62: RESUMEN · EN QUÉ SE GASTÓ MÁS
A63: Por sección | B63: Monto | C63: % del total
A64: Gastos fijos | B64: =$B$25 | C64: =IF(($B$25+$D$59)=0,0,($B$25)/($B$25+$D$59))
A65: Gastos AMEX / tarjeta | B65: =$D$59 | C65: =IF(($B$25+$D$59)=0,0,($D$59)/($B$25+$D$59))
A66: TOTAL | B66: =$B$25+$D$59 | C66: =IF(($B$25+$D$59)=0,0,1)
...

Sheet DICIEMBRE
A1: DICIEMBRE 2026
A3: CONTROL DEL MES
A4: Aporte Loli | B4: Aporte Tito | C4: Sobró del mes anterior | D4: =Total disponible | E4: Total gastado | F4: FALTÓ | G4: SOBRÓ (pasa →)
A5: 0 | B5: 0 | C5: ='NOVIEMBRE'!$G$5 | D5: =A5+B5+C5 | E5: =B25+D59 | F5: =MAX(0,E5-D5) | G5: =MAX(0,D5-E5)
A8: GASTOS FIJOS · monto y medio de pago
A9: Concepto | B9: Monto | C9: Medio de pago
A10: Expensas Núñez
A11: Expensas Pilar
A12: Luz Núñez
A13: Luz Pilar
A14: Wifi Núñez
A15: Wifi Pilar
A16: Paseadora Antonio
A17: Limpieza Núñez
A18: Limpieza Pilar
A19: Netflix
A20: Pilates
A25: Subtotal fijos | B25: =SUM(B10:B24)
A27: GASTOS AMEX / TARJETA · por categoría (se acomoda solo)
A28: Detalle / Comercio | B28: Categoría (auto) | C28: Casa | D28: Monto | E28: Medio de pago
B29: =IF($A29="","",IFERROR(LOOKUP(2,1/((ISNUMBER(SEARCH(CONFIG!$A$3:$A$94,$A29)))*(CONFIG!$A$3:$A$94<>"")),CONFIG!$B$3:$B$94),"Otros"))
B30: =IF($A30="","",IFERROR(LOOKUP(2,1/((ISNUMBER(SEARCH(CONFIG!$A$3:$A$94,$A30)))*(CONFIG!$A$3:$A$94<>"")),CONFIG!$B$3:$B$94),"Otros"))
B31: =IF($A31="","",IFERROR(LOOKUP(2,1/((ISNUMBER(SEARCH(CONFIG!$A$3:$A$94,$A31)))*(CONFIG!$A$3:$A$94<>"")),CONFIG!$B$3:$B$94),"Otros"))
B32: =IF($A32="","",IFERROR(LOOKUP(2,1/((ISNUMBER(SEARCH(CONFIG!$A$3:$A$94,$A32)))*(CONFIG!$A$3:$A$94<>"")),CONFIG!$B$3:$B$94),"Otros"))
B33: =IF($A33="","",IFERROR(LOOKUP(2,1/((ISNUMBER(SEARCH(CONFIG!$A$3:$A$94,$A33)))*(CONFIG!$A$3:$A$94<>"")),CONFIG!$B$3:$B$94),"Otros"))
B34: =IF($A34="","",IFERROR(LOOKUP(2,1/((ISNUMBER(SEARCH(CONFIG!$A$3:$A$94,$A34)))*(CONFIG!$A$3:$A$94<>"")),CONFIG!$B$3:$B$94),"Otros"))
B35: =IF($A35="","",IFERROR(LOOKUP(2,1/((ISNUMBER(SEARCH(CONFIG!$A$3:$A$94,$A35)))*(CONFIG!$A$3:$A$94<>"")),CONFIG!$B$3:$B$94),"Otros"))
B36: =IF($A36="","",IFERROR(LOOKUP(2,1/((ISNUMBER(SEARCH(CONFIG!$A$3:$A$94,$A36)))*(CONFIG!$A$3:$A$94<>"")),CONFIG!$B$3:$B$94),"Otros"))
B37: =IF($A37="","",IFERROR(LOOKUP(2,1/((ISNUMBER(SEARCH(CONFIG!$A$3:$A$94,$A37)))*(CONFIG!$A$3:$A$94<>"")),CONFIG!$B$3:$B$94),"Otros"))
B38: =IF($A38="","",IFERROR(LOOKUP(2,1/((ISNUMBER(SEARCH(CONFIG!$A$3:$A$94,$A38)))*(CONFIG!$A$3:$A$94<>"")),CONFIG!$B$3:$B$94),"Otros"))
B39: =IF($A39="","",IFERROR(LOOKUP(2,1/((ISNUMBER(SEARCH(CONFIG!$A$3:$A$94,$A39)))*(CONFIG!$A$3:$A$94<>"")),CONFIG!$B$3:$B$94),"Otros"))
B40: =IF($A40="","",IFERROR(LOOKUP(2,1/((ISNUMBER(SEARCH(CONFIG!$A$3:$A$94,$A40)))*(CONFIG!$A$3:$A$94<>"")),CONFIG!$B$3:$B$94),"Otros"))
... B58: =IF($A58="","",IFERROR(LOOKUP(2,1/((ISNUMBER(SEARCH(CONFIG!$A$3:$A$94,$A58)))*(CONFIG!$A$3:$A$94<>"")),CONFIG!$B$3:$B$94),"Otros"))
A59: Subtotal AMEX / tarjeta | D59: =SUM(D29:D58)
A60: ➤ Pegá acá el resumen de la AMEX (Detalle + Monto). La categoría se completa sola según el mapa de la hoja CONFIG. No hace falta crear otro archivo.
A62: RESUMEN · EN QUÉ SE GASTÓ MÁS
A63: Por sección | B63: Monto | C63: % del total
A64: Gastos fijos | B64: =$B$25 | C64: =IF(($B$25+$D$59)=0,0,($B$25)/($B$25+$D$59))
A65: Gastos AMEX / tarjeta | B65: =$D$59 | C65: =IF(($B$25+$D$59)=0,0,($D$59)/($B$25+$D$59))
A66: TOTAL | B66: =$B$25+$D$59 | C66: =IF(($B$25+$D$59)=0,0,1)
...

Sheet RESUMEN ANUAL
A1: RESUMEN ANUAL · 2026
A3: Concepto | B3: Jun | C3: Jul | D3: Ago | E3: Sep | F3: Oct | G3: Nov | H3: Dic | I3: TOTAL
A4: Total gastado | B4: ='JUNIO'!$E$5 | C4: ='JULIO'!$E$5 | D4: ='AGOSTO'!$E$5 | E4: ='SEPTIEMBRE'!$E$5 | F4: ='OCTUBRE'!$E$5 | G4: ='NOVIEMBRE'!$E$5 | H4: ='DICIEMBRE'!$E$5 | I4: =SUM(B4:H4)
A5: Aporte Loli | B5: ='JUNIO'!$A$5 | C5: ='JULIO'!$A$5 | D5: ='AGOSTO'!$A$5 | E5: ='SEPTIEMBRE'!$A$5 | F5: ='OCTUBRE'!$A$5 | G5: ='NOVIEMBRE'!$A$5 | H5: ='DICIEMBRE'!$A$5 | I5: =SUM(B5:H5)
A6: Aporte Tito | B6: ='JUNIO'!$B$5 | C6: ='JULIO'!$B$5 | D6: ='AGOSTO'!$B$5 | E6: ='SEPTIEMBRE'!$B$5 | F6: ='OCTUBRE'!$B$5 | G6: ='NOVIEMBRE'!$B$5 | H6: ='DICIEMBRE'!$B$5 | I6: =SUM(B6:H6)
A7: Sobró (saldo a favor) | B7: ='JUNIO'!$G$5 | C7: ='JULIO'!$G$5 | D7: ='AGOSTO'!$G$5 | E7: ='SEPTIEMBRE'!$G$5 | F7: ='OCTUBRE'!$G$5 | G7: ='NOVIEMBRE'!$G$5 | H7: ='DICIEMBRE'!$G$5 | I7: =SUM(B7:H7)
A8: Faltó | B8: ='JUNIO'!$F$5 | C8: ='JULIO'!$F$5 | D8: ='AGOSTO'!$F$5 | E8: ='SEPTIEMBRE'!$F$5 | F8: ='OCTUBRE'!$F$5 | G8: ='NOVIEMBRE'!$F$5 | H8: ='DICIEMBRE'!$F$5 | I8: =SUM(B8:H8)

Sheet CONFIG
A1: MAPA DE CATEGORÍAS · Resumen AMEX (auto) | F1: CATEGORÍAS
A2: Palabra clave (aparece en el detalle) | B2: Categoría | F2: Supermercado | H2: Agregá acá abajo (en amarillo) cualquier comercio nuevo y su categoría. Los meses lo usan para acomodar solo el resumen de la AMEX.
A3: rappi | B3: Delivery | F3: Verdulería
A4: pedidos ya | B4: Delivery | F4: Delivery
A5: pedidosya | B5: Delivery | F5: Cafecito
A6: foodgolf | B6: Delivery | F6: Restaurant
A7: dlorappi | B7: Delivery | F7: Salida
A8: uber eats | B8: Delivery | F8: Nafta
A9: delfin | B9: Supermercado | F9: Transporte
A10: manzana | B10: Supermercado | F10: Veterinaria
A11: manzanares | B11: Supermercado | F11: Farmacia
A12: vacalin | B12: Supermercado | F12: Viaje
A13: paroissien | B13: Supermercado | F13: Trámites
A14: demente | B14: Supermercado | F14: Otros
A15: quesos | B15: Supermercado
A16: coto | B16: Supermercado
A17: carrefour | B17: Supermercado
A18: dia | B18: Supermercado
A19: jumbo | B19: Supermercado
A20: disco | B20: Supermercado
A21: chango | B21: Supermercado
A22: vea | B22: Supermercado
A23: market | B23: Supermercado
A24: rosetta | B24: Supermercado
A25: verdu | B25: Verdulería
A26: fruteria | B26: Verdulería
... A74: monzon | B74: Otros
